Workbook

Sheet Sheet1
A1: CustomerID | B1: Name | C1: Email | D1: Region | E1: Category | F1: PurchaseAmount | G1: Date | H1: Electronics | I1: Missing_Check
A2: C001 | B2: Amit Sharma | C2: amit@gmail.com | D2: North | E2: Electronics | F2: 15000 | G2: 45292 | H2: Clothing | I2: =OR(ISBLANK(C2),ISBLANK(D2),ISBLANK(E2),ISBLANK(F2)) -> FALSE
A3: C002 | B3: Priya Singh | C3: priya@gmail.com | D3: South | E3: Clothing | F3: 8000 | G3: 45293 | H3: Grocery | I3: =OR(ISBLANK(C3),ISBLANK(D3),ISBLANK(E3),ISBLANK(F3)) -> FALSE
A4: C003 | B4: Rahul Verma | C4: ravi@gmail.com | D4: East | E4: Electronics | F4: 12000 | G4: 45294 | H4: Furniture | I4: =OR(ISBLANK(C4),ISBLANK(D4),ISBLANK(E4),ISBLANK(F4)) -> FALSE
A5: C004 | B5: Neha Gupta | C5: neha@gmail.com | D5: West | E5: Grocery | F5: 5000 | G5: 45295 | I5: =OR(ISBLANK(C5),ISBLANK(D5),ISBLANK(E5),ISBLANK(F5)) -> FALSE
A6: C005 | B6: Arjun Mehta | C6: arjun@gmail.com | D6: North | E6: Electronics | F6: 15000 | G6: 45296 | I6: =OR(ISBLANK(C6),ISBLANK(D6),ISBLANK(E6),ISBLANK(F6)) -> FALSE
A7: C006 | B7: Kavya Reddy | C7: kavya@gmail.com | D7: South | E7: Clothng | F7: 7000 | G7: 45297 | I7: =OR(ISBLANK(C7),ISBLANK(D7),ISBLANK(E7),ISBLANK(F7)) -> FALSE
A8: C007 | B8: Simran Kaur | C8: simran@gmail.com | E8: Grocery | F8: 4000 | G8: 45298 | I8: =OR(ISBLANK(C8),ISBLANK(D8),ISBLANK(E8),ISBLANK(F8)) -> TRUE
A9: C008 | B9: Rohit Das | C9: rohit@gmail.com | D9: East | E9: Electronics | G9: 45299 | I9: =OR(ISBLANK(C9),ISBLANK(D9),ISBLANK(E9),ISBLANK(F9)) -> TRUE
A10: C009 | B10: Anjali Nair | C10: anjali@gmail.com | D10: South | E10: Clothing | F10: 8500 | G10: 45300 | I10: =OR(ISBLANK(C10),ISBLANK(D10),ISBLANK(E10),ISBLANK(F10)) -> FALSE
A11: C010 | B11: Amit Sharma | C11: amit@gmail.com | D11: North | E11: Electronics | F11: 15000 | G11: 45292 | I11: =OR(ISBLANK(C11),ISBLANK(D11),ISBLANK(E11),ISBLANK(F11)) -> FALSE
A12: C011 | B12: Varun Kapoor | C12: varun@gmail.com | D12: West | E12: FurNture | F12: 20000 | G12: 45302 | I12: =OR(ISBLANK(C12),ISBLANK(D12),ISBLANK(E12),ISBLANK(F12)) -> FALSE
A13: C012 | B13: Meera Iyer | C13: meera@gmail.com | D13: South | E13: Clothing | F13: 9000 | G13: 45303 | I13: =OR(ISBLANK(C13),ISBLANK(D13),ISBLANK(E13),ISBLANK(F13)) -> FALSE
A14: C013 | B14: Raj Patel | C14: raj@gmail | D14: North | E14: Electronics | F14: 11000 | G14: 45304 | I14: =OR(ISBLANK(C14),ISBLANK(D14),ISBLANK(E14),ISBLANK(F14)) -> FALSE
A15: C014 | B15: Sneha Joshi | C15: sneha@gmail.com | D15: Esat | E15: Grocery | F15: 4500 | G15: 45305 | I15: =OR(ISBLANK(C15),ISBLANK(D15),ISBLANK(E15),ISBLANK(F15)) -> FALSE
A16: C015 | B16: Ali Khan | C16: ali@gmail.com | D16: West | E16: Electronics | F16: 13000 | G16: 45306 | I16: =OR(ISBLANK(C16),ISBLANK(D16),ISBLANK(E16),ISBLANK(F16)) -> FALSE
A17: C016 | B17: Pooja Das | C17: pooja@gail.com | D17: North | E17: Clothing | F17: 7500 | G17: 45307 | I17: =OR(ISBLANK(C17),ISBLANK(D17),ISBLANK(E17),ISBLANK(F17)) -> FALSE
A18: C017 | B18: Rohan Gupta | C18: rohan@gmail.com | D18: South | E18: Electronics | F18: 14000 | G18: 45308 | I18: =OR(ISBLANK(C18),ISBLANK(D18),ISBLANK(E18),ISBLANK(F18)) -> FALSE
A19: C018 | B19: Ankit Jain | C19: ankit@gmail.com | D19: East | E19: Furniture | F19: 22000 | G19: 45309 | I19: =OR(ISBLANK(C19),ISBLANK(D19),ISBLANK(E19),ISBLANK(F19)) -> FALSE
A20: C019 | B20: Divya Sharma | C20: divya@gmail.com | D20: West | E20: Grocery | F20: 4800 | G20: 45310 | I20: =OR(ISBLANK(C20),ISBLANK(D20),ISBLANK(E20),ISBLANK(F20)) -> FALSE
A21: C020 | B21: Karan Malhotra | C21: karan@gmail.com | D21: North | E21: Electronics | F21: 16000 | G21: 45371 | I21: =OR(ISBLANK(C21),ISBLANK(D21),ISBLANK(E21),ISBLANK(F21)) -> FALSE
... A24: C023 | B24: Ritu Kapoor | C24: ritu@gmail.com | D24: West | E24: Grocery | F24: 5100 | G24: 45314 | I24: =OR(ISBLANK(C24),ISBLANK(D24),ISBLANK(E24),ISBLANK(F24)) -> FALSE
A25: C024 | B25: Sachin Yadav | C25: sachin@gmail.com | E25: Furniture | F25: 21000 | G25: 45315 | I25: =OR(ISBLANK(C25),ISBLANK(D25),ISBLANK(E25),ISBLANK(F25)) -> TRUE
A26: C025 | B26: Kritika Mehta | C26: kritika@gmail.com | D26: South | E26: Clthing | F26: 8700 | G26: 45316 | I26: =OR(ISBLANK(C26),ISBLANK(D26),ISBLANK(E26),ISBLANK(F26)) -> FALSE
A27: C026 | B27: Vikas Nair | C27: vikas@gmail.com | D27: East | E27: Electronics | F27: 13500 | G27: 45317 | I27: =OR(ISBLANK(C27),ISBLANK(D27),ISBLANK(E27),ISBLANK(F27)) -> FALSE
A28: C027 | B28: Shreya Iyer | C28: shreya@gmail.com | D28: West | E28: Grocery | F28: 4900 | G28: 45318 | I28: =OR(ISBLANK(C28),ISBLANK(D28),ISBLANK(E28),ISBLANK(F28)) -> FALSE
A29: C028 | B29: Aditya Patel | C29: aditya@gmail.com | D29: North | E29: Electronics | F29: 15500 | G29: 45319 | I29: =OR(ISBLANK(C29),ISBLANK(D29),ISBLANK(E29),ISBLANK(F29)) -> FALSE
A30: C029 | B30: Tanya Sharma | C30: tanya@gmail.com | D30: South | E30: Clothing | F30: 8800 | G30: 45320 | I30: =OR(ISBLANK(C30),ISBLANK(D30),ISBLANK(E30),ISBLANK(F30)) -> FALSE
A31: C030 | B31: Ravi Kumar | C31: ravi@gmail.com | D31: East | E31: Furniture | F31: 23000 | G31: 45321 | I31: =OR(ISBLANK(C31),ISBLANK(D31),ISBLANK(E31),ISBLANK(F31)) -> FALSE
A32: C031 | B32: Neeraj Singh | C32: neeraj@gmail.com | D32: West | E32: Grocery | F32: 5300 | G32: 45322 | I32: =OR(ISBLANK(C32),ISBLANK(D32),ISBLANK(E32),ISBLANK(F32)) -> FALSE
A33: C032 | B33: Ayesha Khan | C33: ayesha@gmail.com | D33: North | E33: Electronics | F33: 14500 | G33: 45323 | I33: =OR(ISBLANK(C33),ISBLANK(D33),ISBLANK(E33),ISBLANK(F33)) -> FALSE
A34: C033 | B34: Deepak Verma | C34: deepak@gmail.com | D34: South | E34: Clothing | F34: 7900 | G34: 45324 | I34: =OR(ISBLANK(C34),ISBLANK(D34),ISBLANK(E34),ISBLANK(F34)) -> FALSE
A35: C034 | B35: Kunal Shah | C35: kunal@gmail.com | D35: East | E35: Elecronics | F35: 13800 | G35: 45325 | I35: =OR(ISBLANK(C35),ISBLANK(D35),ISBLANK(E35),ISBLANK(F35)) -> FALSE
A36: C035 | B36: Payal Jain | C36: payal@gmail.com | D36: West | E36: Grocery | F36: 4700 | G36: 45326 | I36: =OR(ISBLANK(C36),ISBLANK(D36),ISBLANK(E36),ISBLANK(F36)) -> FALSE
A37: C036 | B37: Saurabh Gupta | C37: saurabh@gmail.com | D37: North | E37: Furniture | F37: 20500 | G37: 45327 | I37: =OR(ISBLANK(C37),ISBLANK(D37),ISBLANK(E37),ISBLANK(F37)) -> FALSE
... A39: C038 | B39: Himanshu Patel | C39: himanshu@gmail.com | D39: East | E39: Electronics | F39: 14200 | G39: 45329 | I39: =OR(ISBLANK(C39),ISBLANK(D39),ISBLANK(E39),ISBLANK(F39)) -> FALSE
A40: C039 | B40: Preeti Nair | C40: preeti@gmail.com | E40: Grocery | F40: 5200 | G40: 45330 | I40: =OR(ISBLANK(C40),ISBLANK(D40),ISBLANK(E40),ISBLANK(F40)) -> TRUE
A41: C040 | B41: Rakesh Yadav | C41: rakesh@gmailcom | D41: North | E41: Electronics | F41: 15800 | G41: 45331 | I41: =OR(ISBLANK(C41),ISBLANK(D41),ISBLANK(E41),ISBLANK(F41)) -> FALSE
A42: C041 | B42: Swati Sharma | C42: swati@gmail.com | D42: South | E42: Clothing | F42: 8600 | G42: 45332 | I42: =OR(ISBLANK(C42),ISBLANK(D42),ISBLANK(E42),ISBLANK(F42)) -> FALSE
A43: C042 | B43: Aman Gupta | C43: aman@gmail.com | D43: East | E43: Furniture | F43: 24000 | G43: 45333 | I43: =OR(ISBLANK(C43),ISBLANK(D43),ISBLANK(E43),ISBLANK(F43)) -> FALSE
...

Sheet Sheet2
A1: METRIC | B1: VALUE
A2: Total Customer | B2: =COUNTA(Sheet1!A2:A51) -> 50
A3: Missing Values | B3: =COUNTBLANK(Sheet1!A2:G51) -> 6
A4: Invalid Categories | B4: {=SUMPRODUCT(--(Sheet1!E2:E50<>""),--(COUNTIF(Sheet1!H1:H4,Sheet1!E2:E50)=0))} -> 5
A5: Duplicate Records | B5: {=SUMPRODUCT(--(Sheet1!C2:C50<>""),--(NOT(ISNUMBER(SEARCH("@",Sheet1!C2:C50))*ISNUMBER(SEARCH(".",Sheet1!C2:C50)))))} -> 2
